Workbook

Sheet Hoja1
A1: PRODUCTO | B1: COSTO | C1: COMISION PUNTO ENTREGA | D1: PRECIO | E1: INICIAL
A2: DESPENSA | B2: 155 | C2: 5 | D2: =C2+B2 -> 160 | E2: 6
A3: ACEITE | B3: 30 | C3: 1 | D3: =C3+B3 -> 31 | E3: 7
A4: AGUA | B4: 50 | C4: 5 | D4: =C4+B4 -> 55 | E4: 9
A5: AGUA DE COCO | B5: 20 | C5: 1 | D5: =C5+B5 -> 21 | E5: 19
A6: ARROZ | B6: 18 | C6: 1 | D6: =C6+B6 -> 19 | E6: 5
A7: ATUN | B7: 11 | C7: 1 | D7: =C7+B7 -> 12 | E7: 4
A8: AVENA | B8: 30 | C8: 1 | D8: =C8+B8 -> 31
A9: AZUCAR | B9: 20 | C9: 1 | D9: =C9+B9 -> 21
A10: BOLSA GOLDFISH | B10: 50 | C10: 5 | D10: =C10+B10 -> 55
A11: CAFE | B11: 40 | C11: 1 | D11: =C11+B11 -> 41
A12: CARLOS V KRANKY | B12: 5 | C12: 1 | D12: =C12+B12 -> 6
A13: CARLOS V BARRA | B13: 20 | C13: 3 | D13: =C13+B13 -> 23 | E13: 2
A14: CEREAL BUBBLE | B14: 6 | C14: 1 | D14: =C14+B14 -> 7 | E14: 5
A15: CEREAL METIX | B15: 35 | C15: 1 | D15: =C15+B15 -> 36
A16: CEREAL SLIM | B16: 12 | C16: 1 | D16: =C16+B16 -> 13
A17: CEREAL SUELTO | B17: 12 | C17: 1 | D17: =C17+B17 -> 13 | E17: 14
A18: DELICIAS | B18: 5 | C18: 1 | D18: =C18+B18 -> 6 | E18: 18
A19: ELOTE CHICO | B19: 5 | C19: 1 | D19: =C19+B19 -> 6 | E19: 1
A20: ELOTE GRANDE | B20: 10 | C20: 1 | D20: =C20+B20 -> 11 | E20: 5
A21: FRIJOL | B21: 20 | C21: 1 | D21: =C21+B21 -> 21
A22: GELATINA | B22: 15 | C22: 1 | D22: =C22+B22 -> 16
A23: GRANOLA | B23: 15 | C23: 1 | D23: =C23+B23 -> 16
A24: GOLDFISH | B24: 5 | C24: 1 | D24: =C24+B24 -> 6
A25: GRANOLA | B25: 16 | C25: 1 | D25: =C25+B25 -> 17 | E25: 4
A26: JABON POLVO | B26: 20 | C26: 1 | D26: =C26+B26 -> 21
A27: JABON TRASTES | B27: 25 | C27: 1 | D27: =C27+B27 -> 26
A28: KIT KAT | B28: 35 | C28: 1 | D28: =C28+B28 -> 36 | E28: 3
A29: KNORR | B29: 10 | C29: 1 | D29: =C29+B29 -> 11 | E29: 2
A30: LECHE SC CAJA | B30: 90 | C30: 3 | D30: =C30+B30 -> 93 | E30: 2
A31: LENTEJA | B31: 10 | C31: 1 | D31: =C31+B31 -> 11 | E31: 5
A32: MAIZ | B32: 15 | C32: 1 | D32: =C32+B32 -> 16 | E32: 9
A33: MARUCHAN | B33: 5 | C33: 1 | D33: =C33+B33 -> 6 | E33: 2
A34: MAYONESA 960 | B34: 30 | C34: 1 | D34: =C34+B34 -> 31
A35: MAYONESA 507 | B35: 20 | C35: 1 | D35: =C35+B35 -> 21 | E35: 1
A36: MENTOS | B36: 10 | C36: 1 | D36: =C36+B36 -> 11 | E36: 8
A37: MERMELADA | B37: 10 | C37: 1 | D37: =C37+B37 -> 11
A38: PANDITAS | B38: 25 | C38: 1 | D38: =C38+B38 -> 26 | E38: 6
A39: PAPEL | B39: 19 | C39: 1 | D39: =C39+B39 -> 20
A40: QUESO PHILADELPHIA | B40: 10 | C40: 2 | D40: =C40+B40 -> 12 | E40: 16
...

Sheet Hoja2
A1: ENTRADA | B1: INV FINAL | C1: VENTA CALCULADA | D1: CUOTA VENTA
A2: 20 | C2: =(A2+#REF!)-B2 -> #REF! | D2: =C2*Hoja1!B2 -> #REF!
A3: 24 | C3: =(A3+Hoja1!E2)-B3 -> 30 | D3: =C3*Hoja1!B3 -> 900
C4: =(A4+Hoja1!E3)-B4 -> 7 | D4: =C4*Hoja1!B4 -> 350
C5: =(A5+Hoja1!E4)-B5 -> 9 | D5: =C5*Hoja1!B5 -> 180
C6: =(A6+Hoja1!E5)-B6 -> 19 | D6: =C6*Hoja1!B6 -> 342
B7: 3 | C7: =(A7+Hoja1!E6)-B7 -> 2 | D7: =C7*Hoja1!B7 -> 22
B8: 2 | C8: =(A8+Hoja1!E7)-B8 -> 2 | D8: =C8*Hoja1!B8 -> 60
A9: 20 | C9: =(A9+Hoja1!E8)-B9 -> 20 | D9: =C9*Hoja1!B9 -> 400
A10: 5 | C10: =(A10+Hoja1!E9)-B10 -> 5 | D10: =C10*Hoja1!B10 -> 250
A11: 24 | B11: 15 | C11: =(A11+Hoja1!E10)-B11 -> 9 | D11: =C11*Hoja1!B11 -> 360
A12: 60 | B12: 12 | C12: =(A12+Hoja1!E11)-B12 -> 48 | D12: =C12*Hoja1!B12 -> 240
A13: 25 | B13: 4 | C13: =(A13+Hoja1!E12)-B13 -> 21 | D13: =C13*Hoja1!B13 -> 420
A14: 3 | C14: =(A14+Hoja1!E13)-B14 -> 5 | D14: =C14*Hoja1!B14 -> 30
C15: =(A15+Hoja1!E14)-B15 -> 5 | D15: =C15*Hoja1!B15 -> 175
A16: 5 | C16: =(A16+Hoja1!E15)-B16 -> 5 | D16: =C16*Hoja1!B16 -> 60
C17: =(A17+Hoja1!E16)-B17 -> 0 | D17: =C17*Hoja1!B17 -> 0
A18: 15 | B18: 12 | C18: =(A18+Hoja1!E17)-B18 -> 17 | D18: =C18*Hoja1!B18 -> 85
B19: 18 | C19: =(A19+Hoja1!E18)-B19 -> 0 | D19: =C19*Hoja1!B19 -> 0
A20: 12 | B20: 6 | C20: =(A20+Hoja1!E19)-B20 -> 7 | D20: =C20*Hoja1!B20 -> 70
A21: 5 | C21: =(A21+Hoja1!E20)-B21 -> 10 | D21: =C21*Hoja1!B21 -> 200
C22: =(A22+Hoja1!E21)-B22 -> 0 | D22: =C22*Hoja1!B22 -> 0
A23: 10 | C23: =(A23+Hoja1!E22)-B23 -> 10 | D23: =C23*Hoja1!B23 -> 150
A24: 24 | C24: =(A24+Hoja1!E23)-B24 -> 24 | D24: =C24*Hoja1!B24 -> 120
C25: =(A25+Hoja1!E24)-B25 -> 0 | D25: =C25*Hoja1!B25 -> 0
C26: =(A26+Hoja1!E25)-B26 -> 4 | D26: =C26*Hoja1!B26 -> 80
A27: 4 | C27: =(A27+Hoja1!E26)-B27 -> 4 | D27: =C27*Hoja1!B27 -> 100
A28: 25 | B28: 5 | C28: =(A28+Hoja1!E27)-B28 -> 20 | D28: =C28*Hoja1!B28 -> 700
A29: 10 | C29: =(A29+Hoja1!E28)-B29 -> 13 | D29: =C29*Hoja1!B29 -> 130
C30: =(A30+Hoja1!E29)-B30 -> 2 | D30: =C30*Hoja1!B30 -> 180
C31: =(A31+Hoja1!E30)-B31 -> 2 | D31: =C31*Hoja1!B31 -> 20
C32: =(A32+Hoja1!E31)-B32 -> 5 | D32: =C32*Hoja1!B32 -> 75
A33: 40 | B33: 36 | C33: =(A33+Hoja1!E32)-B33 -> 13 | D33: =C33*Hoja1!B33 -> 65
A34: 10 | C34: =(A34+Hoja1!E33)-B34 -> 12 | D34: =C34*Hoja1!B34 -> 360
C35: =(A35+Hoja1!E34)-B35 -> 0 | D35: =C35*Hoja1!B35 -> 0
A36: 15 | B36: 7 | C36: =(A36+Hoja1!E35)-B36 -> 9 | D36: =C36*Hoja1!B36 -> 90
C37: =(A37+Hoja1!E36)-B37 -> 8 | D37: =C37*Hoja1!B37 -> 80
A38: 10 | C38: =(A38+Hoja1!E37)-B38 -> 10 | D38: =C38*Hoja1!B38 -> 250
A39: 8 | B39: 4 | C39: =(A39+Hoja1!E38)-B39 -> 10 | D39: =C39*Hoja1!B39 -> 190
A40: 20 | C40: =(A40+Hoja1!E39)-B40 -> 20 | D40: =C40*Hoja1!B40 -> 200
...
